[01/04/2017 04:31] ERROR red load_cogs 557: No module named 'dateutil'
Traceback (most recent call last):
  File "red.py", line 554, in load_cogs
    owner_cog._load_cog(extension)
  File "C:\Users\dikoalam\Desktop\Mr.HR\cogs\owner.py", line 796, in _load_cog
    mod_obj = importlib.import_module(cogname)
  File "C:\Users\dikoalam\AppData\Local\Programs\Python\Python36\lib\importlib\__init__.py", line 126, in import_module
    return _bootstrap._gcd_import(name[level:], package, level)
  File "<frozen importlib._bootstrap>", line 978, in _gcd_import
  File "<frozen importlib._bootstrap>", line 961, in _find_and_load
  File "<frozen importlib._bootstrap>", line 950, in _find_and_load_unlocked
  File "<frozen importlib._bootstrap>", line 655, in _load_unlocked
  File "<frozen importlib._bootstrap_external>", line 678, in exec_module
  File "<frozen importlib._bootstrap>", line 205, in _call_with_frames_removed
  File "C:\Users\dikoalam\Desktop\Mr.HR\cogs\interview.py", line 10, in <module>
    from dateutil.relativedelta import relativedelta
ModuleNotFoundError: No module named 'dateutil'
[01/04/2017 04:58] ERROR red on_command_error 363: Exception in command 'reload'
Traceback (most recent call last):
  File "lib\discord\ext\commands\core.py", line 50, in wrapped
    ret = yield from coro(*args, **kwargs)
  File "C:\Users\dikoalam\Desktop\Mr.HR\cogs\owner.py", line 151, in _reload
    self._load_cog(module)
  File "C:\Users\dikoalam\Desktop\Mr.HR\cogs\owner.py", line 796, in _load_cog
    mod_obj = importlib.import_module(cogname)
  File "C:\Users\dikoalam\AppData\Local\Programs\Python\Python36\lib\importlib\__init__.py", line 126, in import_module
    return _bootstrap._gcd_import(name[level:], package, level)
  File "<frozen importlib._bootstrap>", line 978, in _gcd_import
  File "<frozen importlib._bootstrap>", line 961, in _find_and_load
  File "<frozen importlib._bootstrap>", line 950, in _find_and_load_unlocked
  File "<frozen importlib._bootstrap>", line 655, in _load_unlocked
  File "<frozen importlib._bootstrap_external>", line 678, in exec_module
  File "<frozen importlib._bootstrap>", line 205, in _call_with_frames_removed
  File "C:\Users\dikoalam\Desktop\Mr.HR\cogs\owner.py", line 41, in <module>
    class Owner:
  File "C:\Users\dikoalam\Desktop\Mr.HR\cogs\owner.py", line 266, in Owner
    @_set.command(pass_context=True)
NameError: name '_set' is not defined
[01/04/2017 05:00] ERROR red <module> 617: Fatal exception, attempting graceful logout
Traceback (most recent call last):
  File "red.py", line 598, in <module>
    loop.run_until_complete(main(bot))
  File "C:\Users\dikoalam\AppData\Local\Programs\Python\Python36\lib\asyncio\base_events.py", line 466, in run_until_complete
    return future.result()
  File "red.py", line 571, in main
    load_cogs(bot)
  File "red.py", line 528, in load_cogs
    bot.load_extension('cogs.owner')
  File "lib\discord\ext\commands\bot.py", line 732, in load_extension
    lib = importlib.import_module(name)
  File "C:\Users\dikoalam\AppData\Local\Programs\Python\Python36\lib\importlib\__init__.py", line 126, in import_module
    return _bootstrap._gcd_import(name[level:], package, level)
  File "<frozen importlib._bootstrap>", line 978, in _gcd_import
  File "<frozen importlib._bootstrap>", line 961, in _find_and_load
  File "<frozen importlib._bootstrap>", line 950, in _find_and_load_unlocked
  File "<frozen importlib._bootstrap>", line 655, in _load_unlocked
  File "<frozen importlib._bootstrap_external>", line 678, in exec_module
  File "<frozen importlib._bootstrap>", line 205, in _call_with_frames_removed
  File "C:\Users\dikoalam\Desktop\Mr.HR\cogs\owner.py", line 41, in <module>
    class Owner:
  File "C:\Users\dikoalam\Desktop\Mr.HR\cogs\owner.py", line 266, in Owner
    @_set.command(pass_context=True)
NameError: name '_set' is not defined
[01/04/2017 05:00] ERROR red <module> 617: Fatal exception, attempting graceful logout
Traceback (most recent call last):
  File "red.py", line 598, in <module>
    loop.run_until_complete(main(bot))
  File "C:\Users\dikoalam\AppData\Local\Programs\Python\Python36\lib\asyncio\base_events.py", line 466, in run_until_complete
    return future.result()
  File "red.py", line 571, in main
    load_cogs(bot)
  File "red.py", line 528, in load_cogs
    bot.load_extension('cogs.owner')
  File "lib\discord\ext\commands\bot.py", line 732, in load_extension
    lib = importlib.import_module(name)
  File "C:\Users\dikoalam\AppData\Local\Programs\Python\Python36\lib\importlib\__init__.py", line 126, in import_module
    return _bootstrap._gcd_import(name[level:], package, level)
  File "<frozen importlib._bootstrap>", line 978, in _gcd_import
  File "<frozen importlib._bootstrap>", line 961, in _find_and_load
  File "<frozen importlib._bootstrap>", line 950, in _find_and_load_unlocked
  File "<frozen importlib._bootstrap>", line 655, in _load_unlocked
  File "<frozen importlib._bootstrap_external>", line 678, in exec_module
  File "<frozen importlib._bootstrap>", line 205, in _call_with_frames_removed
  File "C:\Users\dikoalam\Desktop\Mr.HR\cogs\owner.py", line 41, in <module>
    class Owner:
  File "C:\Users\dikoalam\Desktop\Mr.HR\cogs\owner.py", line 266, in Owner
    @_set.command(pass_context=True)
NameError: name '_set' is not defined
[01/04/2017 05:00] ERROR red <module> 617: Fatal exception, attempting graceful logout
Traceback (most recent call last):
  File "red.py", line 598, in <module>
    loop.run_until_complete(main(bot))
  File "C:\Users\dikoalam\AppData\Local\Programs\Python\Python36\lib\asyncio\base_events.py", line 466, in run_until_complete
    return future.result()
  File "red.py", line 571, in main
    load_cogs(bot)
  File "red.py", line 528, in load_cogs
    bot.load_extension('cogs.owner')
  File "lib\discord\ext\commands\bot.py", line 732, in load_extension
    lib = importlib.import_module(name)
  File "C:\Users\dikoalam\AppData\Local\Programs\Python\Python36\lib\importlib\__init__.py", line 126, in import_module
    return _bootstrap._gcd_import(name[level:], package, level)
  File "<frozen importlib._bootstrap>", line 978, in _gcd_import
  File "<frozen importlib._bootstrap>", line 961, in _find_and_load
  File "<frozen importlib._bootstrap>", line 950, in _find_and_load_unlocked
  File "<frozen importlib._bootstrap>", line 655, in _load_unlocked
  File "<frozen importlib._bootstrap_external>", line 678, in exec_module
  File "<frozen importlib._bootstrap>", line 205, in _call_with_frames_removed
  File "C:\Users\dikoalam\Desktop\Mr.HR\cogs\owner.py", line 41, in <module>
    class Owner:
  File "C:\Users\dikoalam\Desktop\Mr.HR\cogs\owner.py", line 266, in Owner
    @_set.command(pass_context=True)
NameError: name '_set' is not defined
[01/04/2017 05:00] ERROR red <module> 617: Fatal exception, attempting graceful logout
Traceback (most recent call last):
  File "red.py", line 598, in <module>
    loop.run_until_complete(main(bot))
  File "C:\Users\dikoalam\AppData\Local\Programs\Python\Python36\lib\asyncio\base_events.py", line 466, in run_until_complete
    return future.result()
  File "red.py", line 571, in main
    load_cogs(bot)
  File "red.py", line 528, in load_cogs
    bot.load_extension('cogs.owner')
  File "lib\discord\ext\commands\bot.py", line 732, in load_extension
    lib = importlib.import_module(name)
  File "C:\Users\dikoalam\AppData\Local\Programs\Python\Python36\lib\importlib\__init__.py", line 126, in import_module
    return _bootstrap._gcd_import(name[level:], package, level)
  File "<frozen importlib._bootstrap>", line 978, in _gcd_import
  File "<frozen importlib._bootstrap>", line 961, in _find_and_load
  File "<frozen importlib._bootstrap>", line 950, in _find_and_load_unlocked
  File "<frozen importlib._bootstrap>", line 655, in _load_unlocked
  File "<frozen importlib._bootstrap_external>", line 678, in exec_module
  File "<frozen importlib._bootstrap>", line 205, in _call_with_frames_removed
  File "C:\Users\dikoalam\Desktop\Mr.HR\cogs\owner.py", line 41, in <module>
    class Owner:
  File "C:\Users\dikoalam\Desktop\Mr.HR\cogs\owner.py", line 266, in Owner
    @_set.command(pass_context=True)
NameError: name '_set' is not defined
[01/04/2017 05:00] ERROR red <module> 617: Fatal exception, attempting graceful logout
Traceback (most recent call last):
  File "red.py", line 598, in <module>
    loop.run_until_complete(main(bot))
  File "C:\Users\dikoalam\AppData\Local\Programs\Python\Python36\lib\asyncio\base_events.py", line 466, in run_until_complete
    return future.result()
  File "red.py", line 571, in main
    load_cogs(bot)
  File "red.py", line 528, in load_cogs
    bot.load_extension('cogs.owner')
  File "lib\discord\ext\commands\bot.py", line 732, in load_extension
    lib = importlib.import_module(name)
  File "C:\Users\dikoalam\AppData\Local\Programs\Python\Python36\lib\importlib\__init__.py", line 126, in import_module
    return _bootstrap._gcd_import(name[level:], package, level)
  File "<frozen importlib._bootstrap>", line 978, in _gcd_import
  File "<frozen importlib._bootstrap>", line 961, in _find_and_load
  File "<frozen importlib._bootstrap>", line 950, in _find_and_load_unlocked
  File "<frozen importlib._bootstrap>", line 655, in _load_unlocked
  File "<frozen importlib._bootstrap_external>", line 678, in exec_module
  File "<frozen importlib._bootstrap>", line 205, in _call_with_frames_removed
  File "C:\Users\dikoalam\Desktop\Mr.HR\cogs\owner.py", line 41, in <module>
    class Owner:
  File "C:\Users\dikoalam\Desktop\Mr.HR\cogs\owner.py", line 266, in Owner
    @_set.command(pass_context=True)
NameError: name '_set' is not defined
[01/04/2017 05:00] ERROR red <module> 617: Fatal exception, attempting graceful logout
Traceback (most recent call last):
  File "red.py", line 598, in <module>
    loop.run_until_complete(main(bot))
  File "C:\Users\dikoalam\AppData\Local\Programs\Python\Python36\lib\asyncio\base_events.py", line 466, in run_until_complete
    return future.result()
  File "red.py", line 571, in main
    load_cogs(bot)
  File "red.py", line 528, in load_cogs
    bot.load_extension('cogs.owner')
  File "lib\discord\ext\commands\bot.py", line 732, in load_extension
    lib = importlib.import_module(name)
  File "C:\Users\dikoalam\AppData\Local\Programs\Python\Python36\lib\importlib\__init__.py", line 126, in import_module
    return _bootstrap._gcd_import(name[level:], package, level)
  File "<frozen importlib._bootstrap>", line 978, in _gcd_import
  File "<frozen importlib._bootstrap>", line 961, in _find_and_load
  File "<frozen importlib._bootstrap>", line 950, in _find_and_load_unlocked
  File "<frozen importlib._bootstrap>", line 655, in _load_unlocked
  File "<frozen importlib._bootstrap_external>", line 678, in exec_module
  File "<frozen importlib._bootstrap>", line 205, in _call_with_frames_removed
  File "C:\Users\dikoalam\Desktop\Mr.HR\cogs\owner.py", line 41, in <module>
    class Owner:
  File "C:\Users\dikoalam\Desktop\Mr.HR\cogs\owner.py", line 266, in Owner
    @_set.command(pass_context=True)
NameError: name '_set' is not defined
[01/04/2017 05:00] ERROR red <module> 617: Fatal exception, attempting graceful logout
Traceback (most recent call last):
  File "red.py", line 598, in <module>
    loop.run_until_complete(main(bot))
  File "C:\Users\dikoalam\AppData\Local\Programs\Python\Python36\lib\asyncio\base_events.py", line 466, in run_until_complete
    return future.result()
  File "red.py", line 571, in main
    load_cogs(bot)
  File "red.py", line 528, in load_cogs
    bot.load_extension('cogs.owner')
  File "lib\discord\ext\commands\bot.py", line 732, in load_extension
    lib = importlib.import_module(name)
  File "C:\Users\dikoalam\AppData\Local\Programs\Python\Python36\lib\importlib\__init__.py", line 126, in import_module
    return _bootstrap._gcd_import(name[level:], package, level)
  File "<frozen importlib._bootstrap>", line 978, in _gcd_import
  File "<frozen importlib._bootstrap>", line 961, in _find_and_load
  File "<frozen importlib._bootstrap>", line 950, in _find_and_load_unlocked
  File "<frozen importlib._bootstrap>", line 655, in _load_unlocked
  File "<frozen importlib._bootstrap_external>", line 678, in exec_module
  File "<frozen importlib._bootstrap>", line 205, in _call_with_frames_removed
  File "C:\Users\dikoalam\Desktop\Mr.HR\cogs\owner.py", line 41, in <module>
    class Owner:
  File "C:\Users\dikoalam\Desktop\Mr.HR\cogs\owner.py", line 266, in Owner
    @_set.command(pass_context=True)
NameError: name '_set' is not defined
